#VRML_SIM R2023b utf8

EXTERNPROTO "https://raw.githubusercontent.com/cyberbotics/webots/R2023b/projects/objects/backgrounds/protos/TexturedBackground.proto"
EXTERNPROTO "https://raw.githubusercontent.com/cyberbotics/webots/R2023b/projects/objects/backgrounds/protos/TexturedBackgroundLight.proto"
EXTERNPROTO "https://raw.githubusercontent.com/cyberbotics/webots/R2023b/projects/robots/gctronic/e-puck/protos/E-puck.proto"
EXTERNPROTO "https://raw.githubusercontent.com/cyberbotics/webots/R2023b/projects/objects/floors/protos/Floor.proto"
EXTERNPROTO "https://raw.githubusercontent.com/cyberbotics/webots/R2023b/projects/objects/apartment_structure/protos/Wall.proto"
EXTERNPROTO "https://raw.githubusercontent.com/cyberbotics/webots/R2023b/projects/objects/balls/protos/SoccerBall.proto"
EXTERNPROTO "https://raw.githubusercontent.com/cyberbotics/webots/R2022b/projects/objects/floors/protos/CircleArena.proto"
EXTERNPROTO "https://raw.githubusercontent.com/cyberbotics/webots/R2023b/projects/objects/balls/protos/Ball.proto"
EXTERNPROTO "https://raw.githubusercontent.com/cyberbotics/webots/R2023b/projects/robots/robotis/darwin-op/protos/RobotisOp2.proto"
EXTERNPROTO "https://raw.githubusercontent.com/cyberbotics/webots/R2023b/projects/robots/robotis/darwin-op/protos/RobotisJersey.proto"
EXTERNPROTO "https://raw.githubusercontent.com/cyberbotics/webots/R2023b/projects/samples/contests/robocup/protos/RobocupSoccerField.proto"

WorldInfo {
  basicTimeStep 16
}
Viewpoint {
  orientation -0.0904627427199622 0.7650665953179577 0.6375653667728275 0.495137625424549
  position -3.6509161811369197 -1.3426750665759049 1.7288849791692718
}
TexturedBackground {
}
TexturedBackgroundLight {
}
Floor {
  size 3.5 2
  appearance Parquetry{
    type "dark strip"
  }
}
Wall {
  translation -1.75 -0.01 -0.01
  size 0.05 2 0.25
}
Wall {
  translation 1.75 -0.7 -0.01
  name "wall(4)"
  size 0.05 0.625 0.25
}
Wall {
  translation 1.75 0.7 -0.01
  name "wall(3)"
  size 0.05 0.625 0.25
}
Wall {
  translation -0.0200005 -1.01 0
  rotation 0 0 1 1.5708
  name "wall(1)"
  size 0.05 3.5 0.25
}
Wall {
  translation -0.0200024 0.99 0
  rotation 0 0 1 1.5708
  name "wall(2)"
  size 0.05 3.5 0.25
}
DEF soccer SoccerBall {
  translation 0.98 0.2 0.08
  radius 0.07
  mass 0.5
}
Robot {
  children [
    HingeJoint {
      jointParameters HingeJointParameters {
        axis 0 1 0
        anchor 0 0 0.025
      }

      device [
        RotationalMotor {
          name "left wheel motor"
        }
      ]
      endPoint Solid {
        translation 0 0.045 0.025
        children [
          DEF WHEEL Transform {
            rotation 1 0 0 1.5707996938995747
            children [
              Shape {
                appearance PBRAppearance {
                  baseColor 1 0 0
                  roughness 1
                  metalness 0
                }
                geometry Cylinder {
                  height 0.01
                  radius 0.025
                }
              }
            ]
          }
        ]
        name "left wheel"
        boundingObject USE WHEEL
        physics Physics {
        }
      }
    }
    HingeJoint {
      jointParameters HingeJointParameters {
        axis 0 1 0
        anchor 0 0 0.025
      }
      device [
        RotationalMotor {
          name "right wheel motor"
        }
      ]
      endPoint Solid {
        translation 0 -0.045 0.025
        children [
          USE WHEEL
        ]
        name "right wheel"
        boundingObject USE WHEEL
        physics Physics {
        }
      }
    }
    Transform {
      translation 0 0 0.0415
      children [
        Shape {
          appearance PBRAppearance {
            baseColor 0 0 1
            roughness 1
            metalness 0
          }
          geometry DEF BODY Cylinder {
            height 0.08
            radius 0.045
          }
        }
      ]
    }
    DistanceSensor {
      translation 0.042 0.02 0.063
      rotation 0 0 1 0.5236003061004253
      children [
        DEF SENSOR Transform {
          rotation 0 1 0 1.5708
          children [
            Shape {
              appearance PBRAppearance {
                baseColor 1 1 0
                roughness 1
                metalness 0
              }
              geometry Cylinder {
                height 0.004
                radius 0.008
              }
            }
          ]
        }
      ]
      name "ds0"
      lookupTable [
        0 1020 0
        0.05 1020 0
        0.15 0 0
      ]
      numberOfRays 2
      aperture 1
    }
    DistanceSensor {
      translation 0.042 -0.02 0.063
      rotation 0 0 1 -0.5235996938995747
      children [
        USE SENSOR
      ]
      name "ds1"
      lookupTable [
        0 1020 0
        0.05 1020 0
        0.15 0 0
      ]
      numberOfRays 2
      aperture 1
    }
  ]
  boundingObject Transform {
    translation 0 0 0.0415
    children [
      USE BODY
    ]
  }
  physics Physics {
  }
  controller "<extern>"
  name "my_robot"
}

DEF BALL Ball {
  translation 0.21 -0.270544 0.0395646
  rotation 1 0 0 1.5707963267948966
}
DEF ROBOTISOP2 RobotisOp2 {
  translation 1.1836644972626513 -0.18992731855477596 0.32638848483027677
  controller "soccer"
  jersey RobotisJersey {
    jerseyColor 0 1 0
  }
  name "goalie"
}

DEF ROBOTISOP2 RobotisOp2 {
  translation -1.29 -0.2 0.59
  rotation 0.08803743343552267 0.026206509952906663 0.9957723781819691 -3.100085307179586
  controller "soccer"
  jersey RobotisJersey {
  }
  name "scorer"
}