#VRML_SIM R2023b utf8

EXTERNPROTO "https://raw.githubusercontent.com/cyberbotics/webots/R2023b/projects/objects/backgrounds/protos/TexturedBackground.proto"
EXTERNPROTO "https://raw.githubusercontent.com/cyberbotics/webots/R2023b/projects/objects/backgrounds/protos/TexturedBackgroundLight.proto"
EXTERNPROTO "https://raw.githubusercontent.com/cyberbotics/webots/R2023b/projects/objects/floors/protos/Floor.proto"
EXTERNPROTO "https://raw.githubusercontent.com/cyberbotics/webots/R2023b/projects/objects/apartment_structure/protos/Wall.proto"
IMPORTABLE EXTERNPROTO "https://raw.githubusercontent.com/cyberbotics/webots/R2023b/projects/objects/balls/protos/Ball.proto"

WorldInfo {
  basicTimeStep 16
}
Viewpoint {
  orientation -0.2520210851060381 0.1146247803271558 0.9609092217254063 2.378649759356771
  position 0.829207320257714 -0.7811734204359506 0.7027383884217923
}
TexturedBackground {
}
TexturedBackgroundLight {
}
Floor {
  size 3.5 2
  appearance Parquetry {
    type "dark strip"
  }
}
Wall {
  translation -1.75 -0.01 -0.01
  size 0.05 2 0.25
}
DEF RIGHTGOAL Wall {
  translation 1.75 -0.7 -0.01
  name "wall(4)"
  size 0.05 0.625 0.25
}
DEF LEFTGOAL Wall {
  translation 1.75 0.7 -0.01
  name "wall(3)"
  size 0.05 0.625 0.25
}
Wall {
  translation -0.0200005 -1.01 0
  rotation 0 0 1 1.5708
  name "wall(1)"
  size 0.05 3.5 0.25
}
Wall {
  translation -0.0200024 0.99 0
  rotation 0 0 1 1.5708
  name "wall(2)"
  size 0.05 3.5 0.25
}
DEF PUCK Robot {
  children [
    HingeJoint {
      jointParameters HingeJointParameters {
        axis 0 1 0
        anchor 0 0 0.025
      }
      device [
        RotationalMotor {
          name "left wheel motor"
        }
      ]
      endPoint Solid {
        translation 0 0.045 0.025
        children [
          DEF WHEEL Pose {
            rotation 1 0 0 1.5707996938995747
            children [
              Shape {
                appearance PBRAppearance {
                  baseColor 1 0 0
                  roughness 1
                  metalness 0
                }
                geometry Cylinder {
                  height 0.01
                  radius 0.025
                }
              }
            ]
          }
        ]
        name "left wheel"
        boundingObject USE WHEEL
        physics Physics {
        }
      }
    }
    HingeJoint {
      jointParameters HingeJointParameters {
        axis 0 1 0
        anchor 0 0 0.025
      }
      device [
        RotationalMotor {
          name "right wheel motor"
        }
      ]
      endPoint Solid {
        translation 0 -0.045 0.025
        children [
          USE WHEEL
        ]
        name "right wheel"
        boundingObject USE WHEEL
        physics Physics {
        }
      }
    }
    Pose {
      translation 0 0 0.0415
      children [
        Shape {
          appearance PBRAppearance {
            baseColor 0 0 1
            roughness 1
            metalness 0
          }
          geometry DEF BODY Box {
            size 0.09 0.08 0.07
          }
        }
      ]
    }
    DistanceSensor {
      translation 0.047 0.02 0.063
      rotation 0 0 -1 -5.307179586466759e-06
      children [
        DEF SENSOR Pose {
          rotation 0 1 0 1.5708
          children [
            Shape {
              appearance PBRAppearance {
                baseColor 1 1 0
                roughness 1
                metalness 0
              }
              geometry Cylinder {
                height 0.004
                radius 0.008
              }
            }
          ]
        }
      ]
      name "ds0"
      lookupTable [
        0 1020 0
        0.05 1020 0
        0.15 0 0
      ]
      numberOfRays 2
      aperture 1
    }
    DistanceSensor {
      translation 0.048 -0.02 0.063
      rotation 0 0 -1 9.20018e-07
      children [
        USE SENSOR
      ]
      name "ds1"
      lookupTable [
        0 1020 0
        0.05 1020 0
        0.15 0 0
      ]
      numberOfRays 2
      aperture 1
    }
  ]
  name "my_robot"
  boundingObject Pose {
    translation 0 0 0.0415
    children [
      USE BODY
    ]
  }
  physics Physics {
  }
  controller "<extern>"
  supervisor TRUE
}
